2025-04-17 20:23:04,719 : ERROR : main :  : WindowsDefenderExceptionHandler :  :  : PowerShell command powershell -inputformat none -outputformat text -NonInteractive -Command Get-Item -Path 'Registry::HKEY_LOCAL_MACHINE\SOFTWARE\Microsoft\Windows Defender\Exclusions\Processes' -ErrorAction Stop | Select-Object -ExpandProperty Property did not terminate successfully.
2025-04-17 20:23:04,719 : ERROR : main :  : WindowsDefenderExceptionHandler :  :  : Stderr is:
2025-04-17 20:23:04,719 : ERROR : main :  : WindowsDefenderExceptionHandler :  :  : Get-Item : Requested registry access is not allowed.
2025-04-17 20:23:04,719 : ERROR : main :  : WindowsDefenderExceptionHandler :  :  : At line:1 char:1
2025-04-17 20:23:04,719 : ERROR : main :  : WindowsDefenderExceptionHandler :  :  : + Get-Item -Path 'Registry::HKEY_LOCAL_MACHINE\SOFTWARE\Microsoft\Windo ...
2025-04-17 20:23:04,719 : ERROR : main :  : WindowsDefenderExceptionHandler :  :  : + ~~~~~~~~~~~~~~~~~~~~~~~~~~~~~~~~~~~~~~~~~~~~~~~~~~~~~~~~~~~~~~~~~~~~~
2025-04-17 20:23:04,719 : ERROR : main :  : WindowsDefenderExceptionHandler :  :  :     + CategoryInfo          : PermissionDenied: (HKEY_LOCAL_MACH...sions\Processes:String) [Get-Item], SecurityExcepti 
2025-04-17 20:23:04,719 : ERROR : main :  : WindowsDefenderExceptionHandler :  :  :    on
2025-04-17 20:23:04,719 : ERROR : main :  : WindowsDefenderExceptionHandler :  :  :     + FullyQualifiedErrorId : System.Security.SecurityException,Microsoft.PowerShell.Commands.GetItemCommand
2025-04-17 20:23:04,719 : ERROR : main :  : WindowsDefenderExceptionHandler :  :  :  
2025-04-17 20:30:38,189 : ERROR : Clear OSGi configuration :  : InvokeInstallSiteAction :  :  : Could not clean OSGi configuration area: C:\Program Files\KNIME\configuration\org.eclipse.osgi\299\0\.cp\os\win32\x86_64\localfile_1_0_0.dll
2025-04-17 20:30:54,315 : ERROR : main :  : WindowsDefenderExceptionHandler :  :  : PowerShell command powershell -inputformat none -outputformat text -NonInteractive -Command Get-Item -Path 'Registry::HKEY_LOCAL_MACHINE\SOFTWARE\Microsoft\Windows Defender\Exclusions\Processes' -ErrorAction Stop | Select-Object -ExpandProperty Property did not terminate successfully.
2025-04-17 20:30:54,315 : ERROR : main :  : WindowsDefenderExceptionHandler :  :  : Stderr is:
2025-04-17 20:30:54,315 : ERROR : main :  : WindowsDefenderExceptionHandler :  :  : Get-Item : Requested registry access is not allowed.
2025-04-17 20:30:54,315 : ERROR : main :  : WindowsDefenderExceptionHandler :  :  : At line:1 char:1
2025-04-17 20:30:54,315 : ERROR : main :  : WindowsDefenderExceptionHandler :  :  : + Get-Item -Path 'Registry::HKEY_LOCAL_MACHINE\SOFTWARE\Microsoft\Windo ...
2025-04-17 20:30:54,315 : ERROR : main :  : WindowsDefenderExceptionHandler :  :  : + ~~~~~~~~~~~~~~~~~~~~~~~~~~~~~~~~~~~~~~~~~~~~~~~~~~~~~~~~~~~~~~~~~~~~~
2025-04-17 20:30:54,315 : ERROR : main :  : WindowsDefenderExceptionHandler :  :  :     + CategoryInfo          : PermissionDenied: (HKEY_LOCAL_MACH...sions\Processes:String) [Get-Item], SecurityExcepti 
2025-04-17 20:30:54,315 : ERROR : main :  : WindowsDefenderExceptionHandler :  :  :    on
2025-04-17 20:30:54,315 : ERROR : main :  : WindowsDefenderExceptionHandler :  :  :     + FullyQualifiedErrorId : System.Security.SecurityException,Microsoft.PowerShell.Commands.GetItemCommand
2025-04-17 20:30:54,315 : ERROR : main :  : WindowsDefenderExceptionHandler :  :  :  
2025-04-17 20:36:43,566 : WARN  : ModalContext :  : Node : CSV Writer : 3:32 : Errors loading flow variables into node : Errors overwriting node settings with flow variables: Unknown variable "loans_preprocessed.csv"
2025-04-17 20:36:43,572 : WARN  : ModalContext :  : LoadWorkflowRunnable :  :  : Warnings during load: Status: Warning: 03-classification-preprocessing_deployment.knwf 3 loaded with warnings
2025-04-17 20:36:43,572 : WARN  : ModalContext :  : LoadWorkflowRunnable :  :  :   Status: Warning: 03-classification-preprocessing_deployment.knwf 3
2025-04-17 20:36:43,573 : WARN  : ModalContext :  : LoadWorkflowRunnable :  :  :     Status: Warning: Data Cleaning 3:27
2025-04-17 20:36:43,573 : WARN  : ModalContext :  : LoadWorkflowRunnable :  :  :       Status: Warning: Some node states were invalid
2025-04-17 20:36:43,573 : WARN  : ModalContext :  : LoadWorkflowRunnable :  :  :       Status: Warning: State has changed from CONFIGURED to IDLE
2025-04-17 20:36:43,573 : WARN  : ModalContext :  : LoadWorkflowRunnable :  :  :     Status: Warning: Data Cleaning 3:28
2025-04-17 20:36:43,573 : WARN  : ModalContext :  : LoadWorkflowRunnable :  :  :       Status: Warning: Some node states were invalid
2025-04-17 20:36:43,573 : WARN  : ModalContext :  : LoadWorkflowRunnable :  :  :       Status: Warning: State has changed from CONFIGURED to IDLE
2025-04-17 20:43:15,675 : WARN  : main :  : ExplorerFileSystemUtils :  :  : At least one of the workflows affected by the operation is still open in the editor and has to be saved first.
2025-04-17 20:43:19,051 : WARN  : main :  : ExplorerFileSystemUtils :  :  : At least one of the workflows affected by the operation is still open in the editor and has to be saved first.
2025-04-17 20:44:59,913 : ERROR : KNIME-Worker-15 :  : PythonSourceCodePanel : Python Script : 3:36 : NameError: name 'model_pack' is not defined
org.knime.python2.kernel.PythonIOException: Executing the Python script failed: Traceback (most recent call last):
  File "<string>", line 13, in <module>
NameError: name 'model_pack' is not defined

	at org.knime.python3.scripting.Python3KernelBackend.beautifyPythonTraceback(Python3KernelBackend.java:744)
	at org.knime.python3.scripting.Python3KernelBackend.beautifyPythonTraceback(Python3KernelBackend.java:721)
	at org.knime.python3.scripting.Python3KernelBackend.executeAndCheckOutputs(Python3KernelBackend.java:646)
	at org.knime.python2.kernel.PythonKernel.executeAndCheckOutputs(PythonKernel.java:486)
	at org.knime.python2.kernel.PythonKernelManager.lambda$1(PythonKernelManager.java:208)
	at org.knime.python2.kernel.PythonKernelManager$3.run(PythonKernelManager.java:225)
	at org.knime.core.util.ThreadUtils$RunnableWithContextImpl.runWithContext(ThreadUtils.java:369)
	at org.knime.core.util.ThreadUtils$RunnableWithContext.run(ThreadUtils.java:223)
	at java.base/java.util.concurrent.Executors$RunnableAdapter.call(Unknown Source)
	at java.base/java.util.concurrent.FutureTask.run(Unknown Source)
	at org.knime.core.util.ThreadPool$MyFuture.run(ThreadPool.java:123)
	at org.knime.core.util.ThreadPool$Worker.run(ThreadPool.java:246)
Caused by: Traceback (most recent call last):
  File "<string>", line 13, in <module>
NameError: name 'model_pack' is not defined

2025-04-17 21:00:10,292 : WARN  : KNIME-Worker-16-CSV Reader 3:1 :  : Node : CSV Writer : 3:32 : Errors loading flow variables into node : Errors overwriting node settings with flow variables: Unknown variable "loans_preprocessed.csv"
2025-04-17 21:00:28,086 : ERROR : KNIME-Worker-40-CSV Writer 3:32 :  : Node : CSV Writer : 3:32 : Execute failed: The directory '\home\christoph\PyCharmMiscProject\data' does not exist and must not be created due to user settings.
java.io.IOException: The directory '\home\christoph\PyCharmMiscProject\data' does not exist and must not be created due to user settings.
	at org.knime.base.node.io.filehandling.csv.writer.CSVWriter2NodeModel.createParentDirIfRequired(CSVWriter2NodeModel.java:234)
	at org.knime.base.node.io.filehandling.csv.writer.CSVWriter2NodeModel.execute(CSVWriter2NodeModel.java:144)
	at org.knime.base.node.io.filehandling.csv.writer.CSVWriter2NodeModel.execute(CSVWriter2NodeModel.java:1)
	at org.knime.core.node.NodeModel.executeModel(NodeModel.java:596)
	at org.knime.core.node.Node.invokeFullyNodeModelExecute(Node.java:1284)
	at org.knime.core.node.Node.execute(Node.java:1049)
	at org.knime.core.node.workflow.NativeNodeContainer.performExecuteNode(NativeNodeContainer.java:603)
	at org.knime.core.node.exec.LocalNodeExecutionJob.mainExecute(LocalNodeExecutionJob.java:98)
	at org.knime.core.node.workflow.NodeExecutionJob.internalRun(NodeExecutionJob.java:198)
	at org.knime.core.node.workflow.NodeExecutionJob.run(NodeExecutionJob.java:117)
	at org.knime.core.util.ThreadUtils$RunnableWithContextImpl.runWithContext(ThreadUtils.java:369)
	at org.knime.core.util.ThreadUtils$RunnableWithContext.run(ThreadUtils.java:223)
	at java.base/java.util.concurrent.Executors$RunnableAdapter.call(Unknown Source)
	at java.base/java.util.concurrent.FutureTask.run(Unknown Source)
	at org.knime.core.util.ThreadPool$MyFuture.run(ThreadPool.java:123)
	at org.knime.core.util.ThreadPool$Worker.run(ThreadPool.java:246)
2025-04-17 21:00:36,639 : WARN  : KNIME-Worker-21-Python Script 3:24 :  : PythonScriptNodeModel : Python Script : 3:24 : Traceback (most recent call last):
  File "<string>", line 8, in <module>
2025-04-17 21:00:36,950 : ERROR : KNIME-Worker-21-Python Script 3:24 :  : Node : Python Script : 3:24 : Execute failed: FileNotFoundError: [Errno 2] No such file or directory: 'data/classifier.pkl'
org.knime.core.node.KNIMEException: Execute failed: FileNotFoundError: [Errno 2] No such file or directory: 'data/classifier.pkl'
	at org.knime.python3.scripting.nodes2.PythonScriptNodeModel.checkExecutionAnswer(PythonScriptNodeModel.java:254)
	at org.knime.python3.scripting.nodes2.PythonScriptNodeModel.runUserScript(PythonScriptNodeModel.java:242)
	at org.knime.python3.scripting.nodes2.PythonScriptNodeModel.execute(PythonScriptNodeModel.java:187)
	at org.knime.core.node.NodeModel.executeModel(NodeModel.java:596)
	at org.knime.core.node.Node.invokeFullyNodeModelExecute(Node.java:1284)
	at org.knime.core.node.Node.execute(Node.java:1049)
	at org.knime.core.node.workflow.NativeNodeContainer.performExecuteNode(NativeNodeContainer.java:603)
	at org.knime.core.node.exec.LocalNodeExecutionJob.mainExecute(LocalNodeExecutionJob.java:98)
	at org.knime.core.node.workflow.NodeExecutionJob.internalRun(NodeExecutionJob.java:198)
	at org.knime.core.node.workflow.NodeExecutionJob.run(NodeExecutionJob.java:117)
	at org.knime.core.util.ThreadUtils$RunnableWithContextImpl.runWithContext(ThreadUtils.java:369)
	at org.knime.core.util.ThreadUtils$RunnableWithContext.run(ThreadUtils.java:223)
	at java.base/java.util.concurrent.Executors$RunnableAdapter.call(Unknown Source)
	at java.base/java.util.concurrent.FutureTask.run(Unknown Source)
	at org.knime.core.util.ThreadPool$MyFuture.run(ThreadPool.java:123)
	at org.knime.core.util.ThreadPool$Worker.run(ThreadPool.java:246)
2025-04-17 21:04:25,185 : WARN  : KNIME-Worker-50-Python Script 3:24 :  : PythonScriptNodeModel : Python Script : 3:24 : Traceback (most recent call last):
  File "<string>", line 8, in <module>
2025-04-17 21:04:25,441 : ERROR : KNIME-Worker-50-Python Script 3:24 :  : Node : Python Script : 3:24 : Execute failed: FileNotFoundError: [Errno 2] No such file or directory: 'data/classifier.pkl'
org.knime.core.node.KNIMEException: Execute failed: FileNotFoundError: [Errno 2] No such file or directory: 'data/classifier.pkl'
	at org.knime.python3.scripting.nodes2.PythonScriptNodeModel.checkExecutionAnswer(PythonScriptNodeModel.java:254)
	at org.knime.python3.scripting.nodes2.PythonScriptNodeModel.runUserScript(PythonScriptNodeModel.java:242)
	at org.knime.python3.scripting.nodes2.PythonScriptNodeModel.execute(PythonScriptNodeModel.java:187)
	at org.knime.core.node.NodeModel.executeModel(NodeModel.java:596)
	at org.knime.core.node.Node.invokeFullyNodeModelExecute(Node.java:1284)
	at org.knime.core.node.Node.execute(Node.java:1049)
	at org.knime.core.node.workflow.NativeNodeContainer.performExecuteNode(NativeNodeContainer.java:603)
	at org.knime.core.node.exec.LocalNodeExecutionJob.mainExecute(LocalNodeExecutionJob.java:98)
	at org.knime.core.node.workflow.NodeExecutionJob.internalRun(NodeExecutionJob.java:198)
	at org.knime.core.node.workflow.NodeExecutionJob.run(NodeExecutionJob.java:117)
	at org.knime.core.util.ThreadUtils$RunnableWithContextImpl.runWithContext(ThreadUtils.java:369)
	at org.knime.core.util.ThreadUtils$RunnableWithContext.run(ThreadUtils.java:223)
	at java.base/java.util.concurrent.Executors$RunnableAdapter.call(Unknown Source)
	at java.base/java.util.concurrent.FutureTask.run(Unknown Source)
	at org.knime.core.util.ThreadPool$MyFuture.run(ThreadPool.java:123)
	at org.knime.core.util.ThreadPool$Worker.run(ThreadPool.java:246)
2025-04-17 21:12:54,624 : WARN  : KNIME-Worker-54-Python Script 3:24 :  : PythonScriptNodeModel : Python Script : 3:24 : Traceback (most recent call last):
  File "<string>", line 8, in <module>
2025-04-17 21:12:54,787 : ERROR : KNIME-Worker-54-Python Script 3:24 :  : Node : Python Script : 3:24 : Execute failed: FileNotFoundError: [Errno 2] No such file or directory: 'data/classifier.pkl'
org.knime.core.node.KNIMEException: Execute failed: FileNotFoundError: [Errno 2] No such file or directory: 'data/classifier.pkl'
	at org.knime.python3.scripting.nodes2.PythonScriptNodeModel.checkExecutionAnswer(PythonScriptNodeModel.java:254)
	at org.knime.python3.scripting.nodes2.PythonScriptNodeModel.runUserScript(PythonScriptNodeModel.java:242)
	at org.knime.python3.scripting.nodes2.PythonScriptNodeModel.execute(PythonScriptNodeModel.java:187)
	at org.knime.core.node.NodeModel.executeModel(NodeModel.java:596)
	at org.knime.core.node.Node.invokeFullyNodeModelExecute(Node.java:1284)
	at org.knime.core.node.Node.execute(Node.java:1049)
	at org.knime.core.node.workflow.NativeNodeContainer.performExecuteNode(NativeNodeContainer.java:603)
	at org.knime.core.node.exec.LocalNodeExecutionJob.mainExecute(LocalNodeExecutionJob.java:98)
	at org.knime.core.node.workflow.NodeExecutionJob.internalRun(NodeExecutionJob.java:198)
	at org.knime.core.node.workflow.NodeExecutionJob.run(NodeExecutionJob.java:117)
	at org.knime.core.util.ThreadUtils$RunnableWithContextImpl.runWithContext(ThreadUtils.java:369)
	at org.knime.core.util.ThreadUtils$RunnableWithContext.run(ThreadUtils.java:223)
	at java.base/java.util.concurrent.Executors$RunnableAdapter.call(Unknown Source)
	at java.base/java.util.concurrent.FutureTask.run(Unknown Source)
	at org.knime.core.util.ThreadPool$MyFuture.run(ThreadPool.java:123)
	at org.knime.core.util.ThreadPool$Worker.run(ThreadPool.java:246)
2025-04-17 21:21:09,963 : WARN  : KNIME-Worker-70-Python Script 3:26 :  : PythonScriptNodeModel : Python Script : 3:26 : Traceback (most recent call last):
  File "<string>", line 15, in <module>
2025-04-17 21:21:10,105 : ERROR : KNIME-Worker-70-Python Script 3:26 :  : Node : Python Script : 3:26 : Execute failed: AttributeError: 'dict' object has no attribute 'predict'
org.knime.core.node.KNIMEException: Execute failed: AttributeError: 'dict' object has no attribute 'predict'
	at org.knime.python3.scripting.nodes2.PythonScriptNodeModel.checkExecutionAnswer(PythonScriptNodeModel.java:254)
	at org.knime.python3.scripting.nodes2.PythonScriptNodeModel.runUserScript(PythonScriptNodeModel.java:242)
	at org.knime.python3.scripting.nodes2.PythonScriptNodeModel.execute(PythonScriptNodeModel.java:187)
	at org.knime.core.node.NodeModel.executeModel(NodeModel.java:596)
	at org.knime.core.node.Node.invokeFullyNodeModelExecute(Node.java:1284)
	at org.knime.core.node.Node.execute(Node.java:1049)
	at org.knime.core.node.workflow.NativeNodeContainer.performExecuteNode(NativeNodeContainer.java:603)
	at org.knime.core.node.exec.LocalNodeExecutionJob.mainExecute(LocalNodeExecutionJob.java:98)
	at org.knime.core.node.workflow.NodeExecutionJob.internalRun(NodeExecutionJob.java:198)
	at org.knime.core.node.workflow.NodeExecutionJob.run(NodeExecutionJob.java:117)
	at org.knime.core.util.ThreadUtils$RunnableWithContextImpl.runWithContext(ThreadUtils.java:369)
	at org.knime.core.util.ThreadUtils$RunnableWithContext.run(ThreadUtils.java:223)
	at java.base/java.util.concurrent.Executors$RunnableAdapter.call(Unknown Source)
	at java.base/java.util.concurrent.FutureTask.run(Unknown Source)
	at org.knime.core.util.ThreadPool$MyFuture.run(ThreadPool.java:123)
	at org.knime.core.util.ThreadPool$Worker.run(ThreadPool.java:246)
2025-04-17 21:22:06,071 : WARN  : KNIME-Worker-72-Python Script 3:26 :  : PythonScriptNodeModel : Python Script : 3:26 : Traceback (most recent call last):
  File "<string>", line 15, in <module>
2025-04-17 21:22:06,221 : ERROR : KNIME-Worker-72-Python Script 3:26 :  : Node : Python Script : 3:26 : Execute failed: AttributeError: 'dict' object has no attribute 'predict'
org.knime.core.node.KNIMEException: Execute failed: AttributeError: 'dict' object has no attribute 'predict'
	at org.knime.python3.scripting.nodes2.PythonScriptNodeModel.checkExecutionAnswer(PythonScriptNodeModel.java:254)
	at org.knime.python3.scripting.nodes2.PythonScriptNodeModel.runUserScript(PythonScriptNodeModel.java:242)
	at org.knime.python3.scripting.nodes2.PythonScriptNodeModel.execute(PythonScriptNodeModel.java:187)
	at org.knime.core.node.NodeModel.executeModel(NodeModel.java:596)
	at org.knime.core.node.Node.invokeFullyNodeModelExecute(Node.java:1284)
	at org.knime.core.node.Node.execute(Node.java:1049)
	at org.knime.core.node.workflow.NativeNodeContainer.performExecuteNode(NativeNodeContainer.java:603)
	at org.knime.core.node.exec.LocalNodeExecutionJob.mainExecute(LocalNodeExecutionJob.java:98)
	at org.knime.core.node.workflow.NodeExecutionJob.internalRun(NodeExecutionJob.java:198)
	at org.knime.core.node.workflow.NodeExecutionJob.run(NodeExecutionJob.java:117)
	at org.knime.core.util.ThreadUtils$RunnableWithContextImpl.runWithContext(ThreadUtils.java:369)
	at org.knime.core.util.ThreadUtils$RunnableWithContext.run(ThreadUtils.java:223)
	at java.base/java.util.concurrent.Executors$RunnableAdapter.call(Unknown Source)
	at java.base/java.util.concurrent.FutureTask.run(Unknown Source)
	at org.knime.core.util.ThreadPool$MyFuture.run(ThreadPool.java:123)
	at org.knime.core.util.ThreadPool$Worker.run(ThreadPool.java:246)
2025-04-17 21:39:26,091 : ERROR : KNIME-Worker-74-CSV Writer 3:32 :  : Node : CSV Writer : 3:32 : Execute failed: The directory '\home\christoph\PyCharmMiscProject\data' does not exist and must not be created due to user settings.
java.io.IOException: The directory '\home\christoph\PyCharmMiscProject\data' does not exist and must not be created due to user settings.
	at org.knime.base.node.io.filehandling.csv.writer.CSVWriter2NodeModel.createParentDirIfRequired(CSVWriter2NodeModel.java:234)
	at org.knime.base.node.io.filehandling.csv.writer.CSVWriter2NodeModel.execute(CSVWriter2NodeModel.java:144)
	at org.knime.base.node.io.filehandling.csv.writer.CSVWriter2NodeModel.execute(CSVWriter2NodeModel.java:1)
	at org.knime.core.node.NodeModel.executeModel(NodeModel.java:596)
	at org.knime.core.node.Node.invokeFullyNodeModelExecute(Node.java:1284)
	at org.knime.core.node.Node.execute(Node.java:1049)
	at org.knime.core.node.workflow.NativeNodeContainer.performExecuteNode(NativeNodeContainer.java:603)
	at org.knime.core.node.exec.LocalNodeExecutionJob.mainExecute(LocalNodeExecutionJob.java:98)
	at org.knime.core.node.workflow.NodeExecutionJob.internalRun(NodeExecutionJob.java:198)
	at org.knime.core.node.workflow.NodeExecutionJob.run(NodeExecutionJob.java:117)
	at org.knime.core.util.ThreadUtils$RunnableWithContextImpl.runWithContext(ThreadUtils.java:369)
	at org.knime.core.util.ThreadUtils$RunnableWithContext.run(ThreadUtils.java:223)
	at java.base/java.util.concurrent.Executors$RunnableAdapter.call(Unknown Source)
	at java.base/java.util.concurrent.FutureTask.run(Unknown Source)
	at org.knime.core.util.ThreadPool$MyFuture.run(ThreadPool.java:123)
	at org.knime.core.util.ThreadPool$Worker.run(ThreadPool.java:246)
2025-04-17 21:40:02,034 : WARN  : KNIME-Worker-75-Python Script 3:26 :  : PythonScriptNodeModel : Python Script : 3:26 : Traceback (most recent call last):
  File "<string>", line 15, in <module>
2025-04-17 21:40:02,216 : ERROR : KNIME-Worker-75-Python Script 3:26 :  : Node : Python Script : 3:26 : Execute failed: AttributeError: 'dict' object has no attribute 'predict'
org.knime.core.node.KNIMEException: Execute failed: AttributeError: 'dict' object has no attribute 'predict'
	at org.knime.python3.scripting.nodes2.PythonScriptNodeModel.checkExecutionAnswer(PythonScriptNodeModel.java:254)
	at org.knime.python3.scripting.nodes2.PythonScriptNodeModel.runUserScript(PythonScriptNodeModel.java:242)
	at org.knime.python3.scripting.nodes2.PythonScriptNodeModel.execute(PythonScriptNodeModel.java:187)
	at org.knime.core.node.NodeModel.executeModel(NodeModel.java:596)
	at org.knime.core.node.Node.invokeFullyNodeModelExecute(Node.java:1284)
	at org.knime.core.node.Node.execute(Node.java:1049)
	at org.knime.core.node.workflow.NativeNodeContainer.performExecuteNode(NativeNodeContainer.java:603)
	at org.knime.core.node.exec.LocalNodeExecutionJob.mainExecute(LocalNodeExecutionJob.java:98)
	at org.knime.core.node.workflow.NodeExecutionJob.internalRun(NodeExecutionJob.java:198)
	at org.knime.core.node.workflow.NodeExecutionJob.run(NodeExecutionJob.java:117)
	at org.knime.core.util.ThreadUtils$RunnableWithContextImpl.runWithContext(ThreadUtils.java:369)
	at org.knime.core.util.ThreadUtils$RunnableWithContext.run(ThreadUtils.java:223)
	at java.base/java.util.concurrent.Executors$RunnableAdapter.call(Unknown Source)
	at java.base/java.util.concurrent.FutureTask.run(Unknown Source)
	at org.knime.core.util.ThreadPool$MyFuture.run(ThreadPool.java:123)
	at org.knime.core.util.ThreadPool$Worker.run(ThreadPool.java:246)
2025-04-17 21:40:28,771 : WARN  : KNIME-Worker-77-Python Script 3:26 :  : PythonScriptNodeModel : Python Script : 3:26 : Traceback (most recent call last):
  File "<string>", line 15, in <module>
2025-04-17 21:40:28,919 : ERROR : KNIME-Worker-77-Python Script 3:26 :  : Node : Python Script : 3:26 : Execute failed: AttributeError: 'dict' object has no attribute 'predict'
org.knime.core.node.KNIMEException: Execute failed: AttributeError: 'dict' object has no attribute 'predict'
	at org.knime.python3.scripting.nodes2.PythonScriptNodeModel.checkExecutionAnswer(PythonScriptNodeModel.java:254)
	at org.knime.python3.scripting.nodes2.PythonScriptNodeModel.runUserScript(PythonScriptNodeModel.java:242)
	at org.knime.python3.scripting.nodes2.PythonScriptNodeModel.execute(PythonScriptNodeModel.java:187)
	at org.knime.core.node.NodeModel.executeModel(NodeModel.java:596)
	at org.knime.core.node.Node.invokeFullyNodeModelExecute(Node.java:1284)
	at org.knime.core.node.Node.execute(Node.java:1049)
	at org.knime.core.node.workflow.NativeNodeContainer.performExecuteNode(NativeNodeContainer.java:603)
	at org.knime.core.node.exec.LocalNodeExecutionJob.mainExecute(LocalNodeExecutionJob.java:98)
	at org.knime.core.node.workflow.NodeExecutionJob.internalRun(NodeExecutionJob.java:198)
	at org.knime.core.node.workflow.NodeExecutionJob.run(NodeExecutionJob.java:117)
	at org.knime.core.util.ThreadUtils$RunnableWithContextImpl.runWithContext(ThreadUtils.java:369)
	at org.knime.core.util.ThreadUtils$RunnableWithContext.run(ThreadUtils.java:223)
	at java.base/java.util.concurrent.Executors$RunnableAdapter.call(Unknown Source)
	at java.base/java.util.concurrent.FutureTask.run(Unknown Source)
	at org.knime.core.util.ThreadPool$MyFuture.run(ThreadPool.java:123)
	at org.knime.core.util.ThreadPool$Worker.run(ThreadPool.java:246)
2025-04-17 21:41:46,291 : WARN  : KNIME-Worker-81-Python Script 3:24 :  : PythonScriptNodeModel : Python Script : 3:24 : Traceback (most recent call last):
  File "<string>", line 8, in <module>
2025-04-17 21:41:46,454 : ERROR : KNIME-Worker-81-Python Script 3:24 :  : Node : Python Script : 3:24 : Execute failed: FileNotFoundError: [Errno 2] No such file or directory: 'data/classifier.pkl'
org.knime.core.node.KNIMEException: Execute failed: FileNotFoundError: [Errno 2] No such file or directory: 'data/classifier.pkl'
	at org.knime.python3.scripting.nodes2.PythonScriptNodeModel.checkExecutionAnswer(PythonScriptNodeModel.java:254)
	at org.knime.python3.scripting.nodes2.PythonScriptNodeModel.runUserScript(PythonScriptNodeModel.java:242)
	at org.knime.python3.scripting.nodes2.PythonScriptNodeModel.execute(PythonScriptNodeModel.java:187)
	at org.knime.core.node.NodeModel.executeModel(NodeModel.java:596)
	at org.knime.core.node.Node.invokeFullyNodeModelExecute(Node.java:1284)
	at org.knime.core.node.Node.execute(Node.java:1049)
	at org.knime.core.node.workflow.NativeNodeContainer.performExecuteNode(NativeNodeContainer.java:603)
	at org.knime.core.node.exec.LocalNodeExecutionJob.mainExecute(LocalNodeExecutionJob.java:98)
	at org.knime.core.node.workflow.NodeExecutionJob.internalRun(NodeExecutionJob.java:198)
	at org.knime.core.node.workflow.NodeExecutionJob.run(NodeExecutionJob.java:117)
	at org.knime.core.util.ThreadUtils$RunnableWithContextImpl.runWithContext(ThreadUtils.java:369)
	at org.knime.core.util.ThreadUtils$RunnableWithContext.run(ThreadUtils.java:223)
	at java.base/java.util.concurrent.Executors$RunnableAdapter.call(Unknown Source)
	at java.base/java.util.concurrent.FutureTask.run(Unknown Source)
	at org.knime.core.util.ThreadPool$MyFuture.run(ThreadPool.java:123)
	at org.knime.core.util.ThreadPool$Worker.run(ThreadPool.java:246)
2025-04-17 21:53:27,826 : ERROR : main :  : CEFNodeView :  :  : %cerror%c Console not yet initialized 
      background: #c0392b;
      border-radius: 0.5em;
      color: white;
      font-weight: bold;
      padding: 2px 0.5em;
      [object Object] (source: http://org.knime.core.ui.dialog/uiext-dialog/3_26/assets/index-DKy4BLtd.js; line: 857)
2025-04-17 21:54:03,108 : WARN  : KNIME-Worker-83-Python Script 3:24 :  : PythonScriptNodeModel : Python Script : 3:24 : Traceback (most recent call last):
  File "<string>", line 8, in <module>
2025-04-17 21:54:03,273 : ERROR : KNIME-Worker-83-Python Script 3:24 :  : Node : Python Script : 3:24 : Execute failed: FileNotFoundError: [Errno 2] No such file or directory: 'data/classifier.pkl'
org.knime.core.node.KNIMEException: Execute failed: FileNotFoundError: [Errno 2] No such file or directory: 'data/classifier.pkl'
	at org.knime.python3.scripting.nodes2.PythonScriptNodeModel.checkExecutionAnswer(PythonScriptNodeModel.java:254)
	at org.knime.python3.scripting.nodes2.PythonScriptNodeModel.runUserScript(PythonScriptNodeModel.java:242)
	at org.knime.python3.scripting.nodes2.PythonScriptNodeModel.execute(PythonScriptNodeModel.java:187)
	at org.knime.core.node.NodeModel.executeModel(NodeModel.java:596)
	at org.knime.core.node.Node.invokeFullyNodeModelExecute(Node.java:1284)
	at org.knime.core.node.Node.execute(Node.java:1049)
	at org.knime.core.node.workflow.NativeNodeContainer.performExecuteNode(NativeNodeContainer.java:603)
	at org.knime.core.node.exec.LocalNodeExecutionJob.mainExecute(LocalNodeExecutionJob.java:98)
	at org.knime.core.node.workflow.NodeExecutionJob.internalRun(NodeExecutionJob.java:198)
	at org.knime.core.node.workflow.NodeExecutionJob.run(NodeExecutionJob.java:117)
	at org.knime.core.util.ThreadUtils$RunnableWithContextImpl.runWithContext(ThreadUtils.java:369)
	at org.knime.core.util.ThreadUtils$RunnableWithContext.run(ThreadUtils.java:223)
	at java.base/java.util.concurrent.Executors$RunnableAdapter.call(Unknown Source)
	at java.base/java.util.concurrent.FutureTask.run(Unknown Source)
	at org.knime.core.util.ThreadPool$MyFuture.run(ThreadPool.java:123)
	at org.knime.core.util.ThreadPool$Worker.run(ThreadPool.java:246)
2025-04-17 21:59:51,781 : ERROR : KNIME-Worker-85-Python Script 3:24 :  : Node : Python Script : 3:24 : Execute failed: KnimeUserError: Expected an object in output_objects[0], got None. knio.output_objects[0] has not been populated.
org.knime.core.node.KNIMEException: Execute failed: KnimeUserError: Expected an object in output_objects[0], got None. knio.output_objects[0] has not been populated.
	at org.knime.python3.scripting.nodes2.PythonScriptNodeModel.checkExecutionAnswer(PythonScriptNodeModel.java:254)
	at org.knime.python3.scripting.nodes2.PythonScriptNodeModel.runUserScript(PythonScriptNodeModel.java:242)
	at org.knime.python3.scripting.nodes2.PythonScriptNodeModel.execute(PythonScriptNodeModel.java:187)
	at org.knime.core.node.NodeModel.executeModel(NodeModel.java:596)
	at org.knime.core.node.Node.invokeFullyNodeModelExecute(Node.java:1284)
	at org.knime.core.node.Node.execute(Node.java:1049)
	at org.knime.core.node.workflow.NativeNodeContainer.performExecuteNode(NativeNodeContainer.java:603)
	at org.knime.core.node.exec.LocalNodeExecutionJob.mainExecute(LocalNodeExecutionJob.java:98)
	at org.knime.core.node.workflow.NodeExecutionJob.internalRun(NodeExecutionJob.java:198)
	at org.knime.core.node.workflow.NodeExecutionJob.run(NodeExecutionJob.java:117)
	at org.knime.core.util.ThreadUtils$RunnableWithContextImpl.runWithContext(ThreadUtils.java:369)
	at org.knime.core.util.ThreadUtils$RunnableWithContext.run(ThreadUtils.java:223)
	at java.base/java.util.concurrent.Executors$RunnableAdapter.call(Unknown Source)
	at java.base/java.util.concurrent.FutureTask.run(Unknown Source)
	at org.knime.core.util.ThreadPool$MyFuture.run(ThreadPool.java:123)
	at org.knime.core.util.ThreadPool$Worker.run(ThreadPool.java:246)
2025-04-17 22:01:10,920 : ERROR : main :  : WindowsDefenderExceptionHandler :  :  : PowerShell command powershell -inputformat none -outputformat text -NonInteractive -Command Get-Item -Path 'Registry::HKEY_LOCAL_MACHINE\SOFTWARE\Microsoft\Windows Defender\Exclusions\Processes' -ErrorAction Stop | Select-Object -ExpandProperty Property did not terminate successfully.
2025-04-17 22:01:10,920 : ERROR : main :  : WindowsDefenderExceptionHandler :  :  : Stderr is:
2025-04-17 22:01:10,920 : ERROR : main :  : WindowsDefenderExceptionHandler :  :  : Get-Item : Requested registry access is not allowed.
2025-04-17 22:01:10,920 : ERROR : main :  : WindowsDefenderExceptionHandler :  :  : At line:1 char:1
2025-04-17 22:01:10,920 : ERROR : main :  : WindowsDefenderExceptionHandler :  :  : + Get-Item -Path 'Registry::HKEY_LOCAL_MACHINE\SOFTWARE\Microsoft\Windo ...
2025-04-17 22:01:10,920 : ERROR : main :  : WindowsDefenderExceptionHandler :  :  : + ~~~~~~~~~~~~~~~~~~~~~~~~~~~~~~~~~~~~~~~~~~~~~~~~~~~~~~~~~~~~~~~~~~~~~
2025-04-17 22:01:10,920 : ERROR : main :  : WindowsDefenderExceptionHandler :  :  :     + CategoryInfo          : PermissionDenied: (HKEY_LOCAL_MACH...sions\Processes:String) [Get-Item], SecurityExcepti 
2025-04-17 22:01:10,920 : ERROR : main :  : WindowsDefenderExceptionHandler :  :  :    on
2025-04-17 22:01:10,920 : ERROR : main :  : WindowsDefenderExceptionHandler :  :  :     + FullyQualifiedErrorId : System.Security.SecurityException,Microsoft.PowerShell.Commands.GetItemCommand
2025-04-17 22:01:10,920 : ERROR : main :  : WindowsDefenderExceptionHandler :  :  :  
2025-04-17 22:01:27,707 : WARN  : ModalContext :  : Node : CSV Writer : 3:32 : Errors loading flow variables into node : Errors overwriting node settings with flow variables: Unknown variable "loans_preprocessed.csv"
2025-04-17 22:06:23,224 : ERROR : KNIME-Worker-10 :  : PythonSourceCodePanel : Python Script : 3:36 : FileNotFoundError: [Errno 2] No such file or directory: 'C:\\Users\\SUPERSONIC\\Desktop\\Data Mining\\PS3\\data\\data\\classifier.pkl'
org.knime.python2.kernel.PythonIOException: Executing the Python script failed: Traceback (most recent call last):
  File "<string>", line 11, in <module>
FileNotFoundError: [Errno 2] No such file or directory: 'C:\\Users\\SUPERSONIC\\Desktop\\Data Mining\\PS3\\data\\data\\classifier.pkl'

	at org.knime.python3.scripting.Python3KernelBackend.beautifyPythonTraceback(Python3KernelBackend.java:744)
	at org.knime.python3.scripting.Python3KernelBackend.beautifyPythonTraceback(Python3KernelBackend.java:721)
	at org.knime.python3.scripting.Python3KernelBackend.executeAndCheckOutputs(Python3KernelBackend.java:646)
	at org.knime.python2.kernel.PythonKernel.executeAndCheckOutputs(PythonKernel.java:486)
	at org.knime.python2.kernel.PythonKernelManager.lambda$1(PythonKernelManager.java:208)
	at org.knime.python2.kernel.PythonKernelManager$3.run(PythonKernelManager.java:225)
	at org.knime.core.util.ThreadUtils$RunnableWithContextImpl.runWithContext(ThreadUtils.java:369)
	at org.knime.core.util.ThreadUtils$RunnableWithContext.run(ThreadUtils.java:223)
	at java.base/java.util.concurrent.Executors$RunnableAdapter.call(Unknown Source)
	at java.base/java.util.concurrent.FutureTask.run(Unknown Source)
	at org.knime.core.util.ThreadPool$MyFuture.run(ThreadPool.java:123)
	at org.knime.core.util.ThreadPool$Worker.run(ThreadPool.java:246)
Caused by: Traceback (most recent call last):
  File "<string>", line 11, in <module>
FileNotFoundError: [Errno 2] No such file or directory: 'C:\\Users\\SUPERSONIC\\Desktop\\Data Mining\\PS3\\data\\data\\classifier.pkl'

